2025-04-07 23:35:24,929 [INFO] - train - Loading data from D:\cys\nids\data\processed\CIC-DDoS2019\DNS-testing.csv
2025-04-07 23:35:24,960 [INFO] - train - Running in test mode with reduced dataset
2025-04-07 23:35:24,965 [INFO] - train - Dataset shape: (669, 78)
2025-04-07 23:35:24,965 [INFO] - train - Columns: ['Protocol', 'Flow Duration', 'Total Fwd Packets', 'Total Backward Packets', 'Fwd Packets Length Total', 'Bwd Packets Length Total', 'Fwd Packet Length Max', 'Fwd Packet Length Min', 'Fwd Packet Length Mean', 'Fwd Packet Length Std', 'Bwd Packet Length Max', 'Bwd Packet Length Min', 'Bwd Packet Length Mean', 'Bwd Packet Length Std', 'Flow Bytes/s', 'Flow Packets/s', 'Flow IAT Mean', 'Flow IAT Std', 'Flow IAT Max', 'Flow IAT Min', 'Fwd IAT Total', 'Fwd IAT Mean', 'Fwd IAT Std', 'Fwd IAT Max', 'Fwd IAT Min', 'Bwd IAT Total', 'Bwd IAT Mean', 'Bwd IAT Std', 'Bwd IAT Max', 'Bwd IAT Min', 'Fwd PSH Flags', 'Bwd PSH Flags', 'Fwd URG Flags', 'Bwd URG Flags', 'Fwd Header Length', 'Bwd Header Length', 'Fwd Packets/s', 'Bwd Packets/s', 'Packet Length Min', 'Packet Length Max', 'Packet Length Mean', 'Packet Length Std', 'Packet Length Variance', 'FIN Flag Count', 'SYN Flag Count', 'RST Flag Count', 'PSH Flag Count', 'ACK Flag Count', 'URG Flag Count', 'CWE Flag Count', 'ECE Flag Count', 'Down/Up Ratio', 'Avg Packet Size', 'Avg Fwd Segment Size', 'Avg Bwd Segment Size', 'Fwd Avg Bytes/Bulk', 'Fwd Avg Packets/Bulk', 'Fwd Avg Bulk Rate', 'Bwd Avg Bytes/Bulk', 'Bwd Avg Packets/Bulk', 'Bwd Avg Bulk Rate', 'Subflow Fwd Packets', 'Subflow Fwd Bytes', 'Subflow Bwd Packets', 'Subflow Bwd Bytes', 'Init Fwd Win Bytes', 'Init Bwd Win Bytes', 'Fwd Act Data Packets', 'Fwd Seg Size Min', 'Active Mean', 'Active Std', 'Active Max', 'Active Min', 'Idle Mean', 'Idle Std', 'Idle Max', 'Idle Min', 'Label']
2025-04-07 23:35:24,966 [INFO] - train - Label distribution:
Label
DrDoS_DNS    366
Benign       303
Name: count, dtype: int64
2025-04-07 23:35:24,968 [INFO] - train - Categorical columns: ['Label']
2025-04-07 23:35:24,968 [INFO] - train - Columns to drop: []
2025-04-07 23:35:24,991 [INFO] - train - Scaler saved to d:\cys\nids\models\saved\ensemble_20250407_233524\scaler.joblib
2025-04-07 23:35:24,991 [INFO] - train - Balancing training data classes
2025-04-07 23:35:24,992 [INFO] - train - Class names: ['Benign', 'DrDoS_DNS']
2025-04-07 23:35:32,781 [ERROR] - train - Error during training: y should be a 1d array, got an array of shape (134, 2) instead.
Traceback (most recent call last):
  File "C:\Users\abhijeet sahoo\AppData\Local\Programs\Python\Python312\Lib\argparse.py", line 1943, in _parse_known_args2
    namespace, args = self._parse_known_args(args, namespace, intermixed)
                      ^^^^^^^^^^^^^^^^^^^^^^^^^^^^^^^^^^^^^^^^^^^^^^^^^^^
  File "C:\Users\abhijeet sahoo\AppData\Local\Programs\Python\Python312\Lib\argparse.py", line 2230, in _parse_known_args
    raise ArgumentError(None, _('the following arguments are required: %s') %
argparse.ArgumentError: the following arguments are required: --data/-d

During handling of the above exception, another exception occurred:

Traceback (most recent call last):
  File "d:\cys\nids\train.py", line 247, in <module>
    args = parser.parse_args()
           ^^^^^^^^^^^^^^^^^^^
  File "C:\Users\abhijeet sahoo\AppData\Local\Programs\Python\Python312\Lib\argparse.py", line 1904, in parse_args
    args, argv = self.parse_known_args(args, namespace)
                 ^^^^^^^^^^^^^^^^^^^^^^^^^^^^^^^^^^^^^^
  File "C:\Users\abhijeet sahoo\AppData\Local\Programs\Python\Python312\Lib\argparse.py", line 1914, in parse_known_args
    return self._parse_known_args2(args, namespace, intermixed=False)
           ^^^^^^^^^^^^^^^^^^^^^^^^^^^^^^^^^^^^^^^^^^^^^^^^^^^^^^^^^^
  File "C:\Users\abhijeet sahoo\AppData\Local\Programs\Python\Python312\Lib\argparse.py", line 1945, in _parse_known_args2
    self.error(str(err))
  File "C:\Users\abhijeet sahoo\AppData\Local\Programs\Python\Python312\Lib\argparse.py", line 2650, in error
    self.exit(2, _('%(prog)s: error: %(message)s\n') % args)
  File "C:\Users\abhijeet sahoo\AppData\Local\Programs\Python\Python312\Lib\argparse.py", line 2637, in exit
    _sys.exit(status)
SystemExit: 2

During handling of the above exception, another exception occurred:

Traceback (most recent call last):
  File "d:\cys\nids\train.py", line 189, in train_models
    metrics = model.evaluate(X_test, y_test, eval_dir)
              ^^^^^^^^^^^^^^^^^^^^^^^^^^^^^^^^^^^^^^^^
  File "d:\cys\nids\models\ensemble.py", line 158, in evaluate
    xgb_metrics = self.xgb_model.evaluate(X_test, y_test,
                 ^^^^^^^^^^^^^^^^^^^^^^^^^^^^^^^^^^^^^^^
  File "d:\cys\nids\models\xgboost_model.py", line 195, in evaluate
    y_pred = self.predict(X_test)
             ^^^^^^^^^^^^^^^^^^^^
  File "d:\cys\nids\models\xgboost_model.py", line 146, in predict
    return self.label_encoder.inverse_transform(predictions)
           ^^^^^^^^^^^^^^^^^^^^^^^^^^^^^^^^^^^^^^^^^^^^^^^^^
  File "D:\cys\nids\.venv\Lib\site-packages\sklearn\preprocessing\_label.py", line 151, in inverse_transform
    y = column_or_1d(y, warn=True)
        ^^^^^^^^^^^^^^^^^^^^^^^^^^
  File "D:\cys\nids\.venv\Lib\site-packages\sklearn\utils\validation.py", line 1485, in column_or_1d
    raise ValueError(
ValueError: y should be a 1d array, got an array of shape (134, 2) instead.
